Workbook

Sheet 📊 RawData
A1: Day 6 — Regression Analysis | Student Performance Dataset | 80 Rows
A2: ID | B2: Name | C2: Department | D2: StudyHours | E2: Attendance% | F2: Income(£) | G2: Score | H2: Pass | I2: Is_Eng | J2: Is_Mkt
A3: 1 | B3: S001 | C3: Marketing | D3: 5.3 | E3: 84.6 | F3: 34200 | G3: 100 | H3: 1 | I3: 0 | J3: 1
A4: 2 | B4: S002 | C4: Engineering | D4: 3 | E4: 89.2 | F4: 10000 | G4: 84.8 | H4: 1 | I4: 1 | J4: 0
A5: 3 | B5: S003 | C5: Marketing | D5: 2.8 | E5: 85.2 | F5: 40300 | G5: 92.8 | H5: 1 | I5: 0 | J5: 1
A6: 4 | B6: S004 | C6: Marketing | D6: 2.9 | E6: 88.8 | F6: 45900 | G6: 88.9 | H6: 1 | I6: 0 | J6: 1
A7: 5 | B7: S005 | C7: Science | D7: 2.7 | E7: 100 | F7: 10200 | G7: 85.5 | H7: 1 | I7: 0 | J7: 0
A8: 6 | B8: S006 | C8: Marketing | D8: 3.8 | E8: 83 | F8: 43400 | G8: 83.9 | H8: 1 | I8: 0 | J8: 1
A9: 7 | B9: S007 | C9: Finance | D9: 3 | E9: 75.4 | F9: 49500 | G9: 74.2 | H9: 1 | I9: 0 | J9: 0
A10: 8 | B10: S008 | C10: Finance | D10: 4.2 | E10: 84 | F10: 41300 | G10: 85 | H10: 1 | I10: 0 | J10: 0
A11: 9 | B11: S009 | C11: Science | D11: 0.8 | E11: 60.3 | F11: 53300 | G11: 64 | H11: 1 | I11: 0 | J11: 0
A12: 10 | B12: S010 | C12: Engineering | D12: 7 | E12: 79.8 | F12: 36400 | G12: 99.9 | H12: 1 | I12: 1 | J12: 0
A13: 11 | B13: S011 | C13: Marketing | D13: 6.3 | E13: 82.9 | F13: 46500 | G13: 94.4 | H13: 1 | I13: 0 | J13: 1
A14: 12 | B14: S012 | C14: Marketing | D14: 6 | E14: 96.4 | F14: 43100 | G14: 98.5 | H14: 1 | I14: 0 | J14: 1
... A82: 80 | B82: S080 | C82: Marketing | D82: 5.1 | E82: 75.7 | F82: 38500 | G82: 90.7 | H82: 1 | I82: 0 | J82: 1

Sheet 📉 SimpleRegression
A1: Simple Linear Regression — Manual Method (y = β₀ + β₁ × StudyHours)
A2: What this does: Finds the BEST STRAIGHT LINE through the data. β₁ = slope (effect per study hour). β₀ = intercept (score when hours=0). R² = % of score variation explained by study hours.
F3: Training Data + Predictions + Residuals
A4: Model Parameters | F4: StudyHours | G4: ActualScore | H4: PredictedScore | I4: Residual | J4: AbsError | K4: SqError | L4: MAPEError
A5: β₁ (Slope) | B5: =SLOPE('📊 RawData'!G3:G82,'📊 RawData'!D3:D82) -> 2.9341594 | C5: ← | D5: Score gain per extra study hour | F5: ='📊 RawData'!D3 -> 5.3 | G5: ='📊 RawData'!G3 -> 100 | H5: =ROUND($B$6+$B$5*F5,1) -> 90.8 | I5: =G5-H5 -> 9.2 | J5: =ABS(I5) -> 9.2 | K5: =I5^2 -> 84.64 | L5: =ABS((G5-H5)/G5) -> 0.092
A6: β₀ (Intercept) | B6: =INTERCEPT('📊 RawData'!G3:G82,'📊 RawData'!D3:D82) -> 75.240706 | C6: ← | D6: Predicted score when study hours = 0 | F6: ='📊 RawData'!D4 -> 3 | G6: ='📊 RawData'!G4 -> 84.8 | H6: =ROUND($B$6+$B$5*F6,1) -> 84 | I6: =G6-H6 -> 0.8 | J6: =ABS(I6) -> 0.8 | K6: =I6^2 -> 0.64 | L6: =ABS((G6-H6)/G6) -> 0.0094339623
A7: R² (R-Squared) | B7: =RSQ('📊 RawData'!G3:G82,'📊 RawData'!D3:D82) -> 0.34928941 | C7: ← | D7: % of score variance explained by study hours | F7: ='📊 RawData'!D5 -> 2.8 | G7: ='📊 RawData'!G5 -> 92.8 | H7: =ROUND($B$6+$B$5*F7,1) -> 83.5 | I7: =G7-H7 -> 9.3 | J7: =ABS(I7) -> 9.3 | K7: =I7^2 -> 86.49 | L7: =ABS((G7-H7)/G7) -> 0.10021552
A8: r (Correlation) | B8: =CORREL('📊 RawData'!G3:G82,'📊 RawData'!D3:D82) -> 0.59100712 | C8: ← | D8: Pearson correlation coefficient | F8: ='📊 RawData'!D6 -> 2.9 | G8: ='📊 RawData'!G6 -> 88.9 | H8: =ROUND($B$6+$B$5*F8,1) -> 83.7 | I8: =G8-H8 -> 5.2 | J8: =ABS(I8) -> 5.2 | K8: =I8^2 -> 27.04 | L8: =ABS((G8-H8)/G8) -> 0.058492688
A9: Std Error | B9: 6.6288 | C9: ← | D9: Average prediction error in score points | F9: ='📊 RawData'!D7 -> 2.7 | G9: ='📊 RawData'!G7 -> 85.5 | H9: =ROUND($B$6+$B$5*F9,1) -> 83.2 | I9: =G9-H9 -> 2.3 | J9: =ABS(I9) -> 2.3 | K9: =I9^2 -> 5.29 | L9: =ABS((G9-H9)/G9) -> 0.026900585
A10: n (Rows) | B10: =COUNT('📊 RawData'!D3:D82) -> 80 | C10: ← | D10: Number of data points used | F10: ='📊 RawData'!D8 -> 3.8 | G10: ='📊 RawData'!G8 -> 83.9 | H10: =ROUND($B$6+$B$5*F10,1) -> 86.4 | I10: =G10-H10 -> -2.5 | J10: =ABS(I10) -> 2.5 | K10: =I10^2 -> 6.25 | L10: =ABS((G10-H10)/G10) -> 0.029797378
F11: ='📊 RawData'!D9 -> 3 | G11: ='📊 RawData'!G9 -> 74.2 | H11: =ROUND($B$6+$B$5*F11,1) -> 84 | I11: =G11-H11 -> -9.8 | J11: =ABS(I11) -> 9.8 | K11: =I11^2 -> 96.04 | L11: =ABS((G11-H11)/G11) -> 0.13207547
A12: 📐 MODEL EQUATION: Score = [β₀] + [β₁] × StudyHours | F12: ='📊 RawData'!D10 -> 4.2 | G12: ='📊 RawData'!G10 -> 85 | H12: =ROUND($B$6+$B$5*F12,1) -> 87.6 | I12: =G12-H12 -> -2.6 | J12: =ABS(I12) -> 2.6 | K12: =I12^2 -> 6.76 | L12: =ABS((G12-H12)/G12) -> 0.030588235
A13: =CONCATENATE("Score = ",TEXT(B6,"0.00")," + ",TEXT(B5,"0.00")," × StudyHours") -> Score = 75.24 + 2.93 × StudyHours | F13: ='📊 RawData'!D11 -> 0.8 | G13: ='📊 RawData'!G11 -> 64 | H13: =ROUND($B$6+$B$5*F13,1) -> 77.6 | I13: =G13-H13 -> -13.6 | J13: =ABS(I13) -> 13.6 | K13: =I13^2 -> 184.96 | L13: =ABS((G13-H13)/G13) -> 0.2125
F14: ='📊 RawData'!D12 -> 7 | G14: ='📊 RawData'!G12 -> 99.9 | H14: =ROUND($B$6+$B$5*F14,1) -> 95.8 | I14: =G14-H14 -> 4.1 | J14: =ABS(I14) -> 4.1 | K14: =I14^2 -> 16.81 | L14: =ABS((G14-H14)/G14) -> 0.041041041
A15: VERIFY YOUR MODEL: 1. AVERAGE(Residuals) ≈ 0.00 — mathematical property of OLS 2. PredictedScore formula matches β₀ + β₁ × StudyHours 3. FORECAST.LINEAR(5, Score_col, Hours_col) should match formula result for x=5 | F15: ='📊 RawData'!D13 -> 6.3 | G15: ='📊 RawData'!G13 -> 94.4 | H15: =ROUND($B$6+$B$5*F15,1) -> 93.7 | I15: =G15-H15 -> 0.7 | J15: =ABS(I15) -> 0.7 | K15: =I15^2 -> 0.49 | L15: =ABS((G15-H15)/G15) -> 0.0074152542
F16: ='📊 RawData'!D14 -> 6 | G16: ='📊 RawData'!G14 -> 98.5 | H16: =ROUND($B$6+$B$5*F16,1) -> 92.8 | I16: =G16-H16 -> 5.7 | J16: =ABS(I16) -> 5.7 | K16: =I16^2 -> 32.49 | L16: =ABS((G16-H16)/G16) -> 0.05786802
F17: ='📊 RawData'!D15 -> 2.5 | G17: ='📊 RawData'!G15 -> 93.3 | H17: =ROUND($B$6+$B$5*F17,1) -> 82.6 | I17: =G17-H17 -> 10.7 | J17: =ABS(I17) -> 10.7 | K17: =I17^2 -> 114.49 | L17: =ABS((G17-H17)/G17) -> 0.11468382
F18: ='📊 RawData'!D16 -> 7.4 | G18: ='📊 RawData'!G16 -> 97.4 | H18: =ROUND($B$6+$B$5*F18,1) -> 97 | I18: =G18-H18 -> 0.4 | J18: =ABS(I18) -> 0.4 | K18: =I18^2 -> 0.16 | L18: =ABS((G18-H18)/G18) -> 0.0041067762
F19: ='📊 RawData'!D17 -> 4.3 | G19: ='📊 RawData'!G17 -> 91 | H19: =ROUND($B$6+$B$5*F19,1) -> 87.9 | I19: =G19-H19 -> 3.1 | J19: =ABS(I19) -> 3.1 | K19: =I19^2 -> 9.61 | L19: =ABS((G19-H19)/G19) -> 0.034065934
A20: Prediction for New Study Hours | F20: ='📊 RawData'!D18 -> 5.7 | G20: ='📊 RawData'!G18 -> 94.1 | H20: =ROUND($B$6+$B$5*F20,1) -> 92 | I20: =G20-H20 -> 2.1 | J20: =ABS(I20) -> 2.1 | K20: =I20^2 -> 4.41 | L20: =ABS((G20-H20)/G20) -> 0.022316684
A21: StudyHours (Input) | B21: Predicted Score | C21: Lower 95% CI | D21: Upper 95% CI | F21: ='📊 RawData'!D19 -> 5.5 | G21: ='📊 RawData'!G19 -> 87.4 | H21: =ROUND($B$6+$B$5*F21,1) -> 91.4 | I21: =G21-H21 -> -4 | J21: =ABS(I21) -> 4 | K21: =I21^2 -> 16 | L21: =ABS((G21-H21)/G21) -> 0.04576659
A22: 1 | B22: =ROUND($B$6+$B$5*A22,1) -> 78.2 | C22: =ROUND(B22-1.96*$B$9,1) -> 65.2 | D22: =ROUND(B22+1.96*$B$9,1) -> 91.2 | F22: ='📊 RawData'!D20 -> 4.4 | G22: ='📊 RawData'!G20 -> 96.3 | H22: =ROUND($B$6+$B$5*F22,1) -> 88.2 | I22: =G22-H22 -> 8.1 | J22: =ABS(I22) -> 8.1 | K22: =I22^2 -> 65.61 | L22: =ABS((G22-H22)/G22) -> 0.08411215
A23: 2 | B23: =ROUND($B$6+$B$5*A23,1) -> 81.1 | C23: =ROUND(B23-1.96*$B$9,1) -> 68.1 | D23: =ROUND(B23+1.96*$B$9,1) -> 94.1 | F23: ='📊 RawData'!D21 -> 5.8 | G23: ='📊 RawData'!G21 -> 90.4 | H23: =ROUND($B$6+$B$5*F23,1) -> 92.3 | I23: =G23-H23 -> -1.9 | J23: =ABS(I23) -> 1.9 | K23: =I23^2 -> 3.61 | L23: =ABS((G23-H23)/G23) -> 0.021017699
A24: 3 | B24: =ROUND($B$6+$B$5*A24,1) -> 84 | C24: =ROUND(B24-1.96*$B$9,1) -> 71 | D24: =ROUND(B24+1.96*$B$9,1) -> 97 | F24: ='📊 RawData'!D22 -> 8 | G24: ='📊 RawData'!G22 -> 94.5 | H24: =ROUND($B$6+$B$5*F24,1) -> 98.7 | I24: =G24-H24 -> -4.2 | J24: =ABS(I24) -> 4.2 | K24: =I24^2 -> 17.64 | L24: =ABS((G24-H24)/G24) -> 0.044444444
A25: 4 | B25: =ROUND($B$6+$B$5*A25,1) -> 87 | C25: =ROUND(B25-1.96*$B$9,1) -> 74 | D25: =ROUND(B25+1.96*$B$9,1) -> 100 | F25: ='📊 RawData'!D23 -> 4 | G25: ='📊 RawData'!G23 -> 83.3 | H25: =ROUND($B$6+$B$5*F25,1) -> 87 | I25: =G25-H25 -> -3.7 | J25: =ABS(I25) -> 3.7 | K25: =I25^2 -> 13.69 | L25: =ABS((G25-H25)/G25) -> 0.044417767
A26: 5 | B26: =ROUND($B$6+$B$5*A26,1) -> 89.9 | C26: =ROUND(B26-1.96*$B$9,1) -> 76.9 | D26: =ROUND(B26+1.96*$B$9,1) -> 102.9 | F26: ='📊 RawData'!D24 -> 4.8 | G26: ='📊 RawData'!G24 -> 76.6 | H26: =ROUND($B$6+$B$5*F26,1) -> 89.3 | I26: =G26-H26 -> -12.7 | J26: =ABS(I26) -> 12.7 | K26: =I26^2 -> 161.29 | L26: =ABS((G26-H26)/G26) -> 0.16579634
A27: 6 | B27: =ROUND($B$6+$B$5*A27,1) -> 92.8 | C27: =ROUND(B27-1.96*$B$9,1) -> 79.8 | D27: =ROUND(B27+1.96*$B$9,1) -> 105.8 | F27: ='📊 RawData'!D25 -> 4.1 | G27: ='📊 RawData'!G25 -> 98 | H27: =ROUND($B$6+$B$5*F27,1) -> 87.3 | I27: =G27-H27 -> 10.7 | J27: =ABS(I27) -> 10.7 | K27: =I27^2 -> 114.49 | L27: =ABS((G27-H27)/G27) -> 0.10918367
A28: 7 | B28: =ROUND($B$6+$B$5*A28,1) -> 95.8 | C28: =ROUND(B28-1.96*$B$9,1) -> 82.8 | D28: =ROUND(B28+1.96*$B$9,1) -> 108.8 | F28: ='📊 RawData'!D26 -> 4.9 | G28: ='📊 RawData'!G26 -> 85.1 | H28: =ROUND($B$6+$B$5*F28,1) -> 89.6 | I28: =G28-H28 -> -4.5 | J28: =ABS(I28) -> 4.5 | K28: =I28^2 -> 20.25 | L28: =ABS((G28-H28)/G28) -> 0.052878966
A29: 8 | B29: =ROUND($B$6+$B$5*A29,1) -> 98.7 | C29: =ROUND(B29-1.96*$B$9,1) -> 85.7 | D29: =ROUND(B29+1.96*$B$9,1) -> 111.7 | F29: ='📊 RawData'!D27 -> 0.9 | G29: ='📊 RawData'!G27 -> 83.7 | H29: =ROUND($B$6+$B$5*F29,1) -> 77.9 | I29: =G29-H29 -> 5.8 | J29: =ABS(I29) -> 5.8 | K29: =I29^2 -> 33.64 | L29: =ABS((G29-H29)/G29) -> 0.069295102
A30: 9 | B30: =ROUND($B$6+$B$5*A30,1) -> 101.6 | C30: =ROUND(B30-1.96*$B$9,1) -> 88.6 | D30: =ROUND(B30+1.96*$B$9,1) -> 114.6 | F30: ='📊 RawData'!D28 -> 3.7 | G30: ='📊 RawData'!G28 -> 86.6 | H30: =ROUND($B$6+$B$5*F30,1) -> 86.1 | I30: =G30-H30 -> 0.5 | J30: =ABS(I30) -> 0.5 | K30: =I30^2 -> 0.25 | L30: =ABS((G30-H30)/G30) -> 0.0057736721
A31: 10 | B31: =ROUND($B$6+$B$5*A31,1) -> 104.6 | C31: =ROUND(B31-1.96*$B$9,1) -> 91.6 | D31: =ROUND(B31+1.96*$B$9,1) -> 117.6 | F31: ='📊 RawData'!D29 -> 7.7 | G31: ='📊 RawData'!G29 -> 100 | H31: =ROUND($B$6+$B$5*F31,1) -> 97.8 | I31: =G31-H31 -> 2.2 | J31: =ABS(I31) -> 2.2 | K31: =I31^2 -> 4.84 | L31: =ABS((G31-H31)/G31) -> 0.022
F32: ='📊 RawData'!D30 -> 3.5 | G32: ='📊 RawData'!G30 -> 71.5 | H32: =ROUND($B$6+$B$5*F32,1) -> 85.5 | I32: =G32-H32 -> -14 | J32: =ABS(I32) -> 14 | K32: =I32^2 -> 196 | L32: =ABS((G32-H32)/G32) -> 0.1958042
F33: ='📊 RawData'!D31 -> 4.4 | G33: ='📊 RawData'!G31 -> 82.1 | H33: =ROUND($B$6+$B$5*F33,1) -> 88.2 | I33: =G33-H33 -> -6.1 | J33: =ABS(I33) -> 6.1 | K33: =I33^2 -> 37.21 | L33: =ABS((G33-H33)/G33) -> 0.074299635
F34: ='📊 RawData'!D32 -> 5.9 | G34: ='📊 RawData'!G32 -> 87.9 | H34: =ROUND($B$6+$B$5*F34,1) -> 92.6 | I34: =G34-H34 -> -4.7 | J34: =ABS(I34) -> 4.7 | K34: =I34^2 -> 22.09 | L34: =ABS((G34-H34)/G34) -> 0.053469852
F35: ='📊 RawData'!D33 -> 6.7 | G35: ='📊 RawData'!G33 -> 97.1 | H35: =ROUND($B$6+$B$5*F35,1) -> 94.9 | I35: =G35-H35 -> 2.2 | J35: =ABS(I35) -> 2.2 | K35: =I35^2 -> 4.84 | L35: =ABS((G35-H35)/G35) -> 0.022657055
F36: ='📊 RawData'!D34 -> 5 | G36: ='📊 RawData'!G34 -> 81.8 | H36: =ROUND($B$6+$B$5*F36,1) -> 89.9 | I36: =G36-H36 -> -8.1 | J36: =ABS(I36) -> 8.1 | K36: =I36^2 -> 65.61 | L36: =ABS((G36-H36)/G36) -> 0.099022005
F37: ='📊 RawData'!D35 -> 5 | G37: ='📊 RawData'!G35 -> 89.1 | H37: =ROUND($B$6+$B$5*F37,1) -> 89.9 | I37: =G37-H37 -> -0.8 | J37: =ABS(I37) -> 0.8 | K37: =I37^2 -> 0.64 | L37: =ABS((G37-H37)/G37) -> 0.0089786756
F38: ='📊 RawData'!D36 -> 2.9 | G38: ='📊 RawData'!G36 -> 73.1 | H38: =ROUND($B$6+$B$5*F38,1) -> 83.7 | I38: =G38-H38 -> -10.6 | J38: =ABS(I38) -> 10.6 | K38: =I38^2 -> 112.36 | L38: =ABS((G38-H38)/G38) -> 0.14500684
F39: ='📊 RawData'!D37 -> 6.2 | G39: ='📊 RawData'!G37 -> 92.6 | H39: =ROUND($B$6+$B$5*F39,1) -> 93.4 | I39: =G39-H39 -> -0.8 | J39: =ABS(I39) -> 0.8 | K39: =I39^2 -> 0.64 | L39: =ABS((G39-H39)/G39) -> 0.0086393089
F40: ='📊 RawData'!D38 -> 3.4 | G40: ='📊 RawData'!G38 -> 81.1 | H40: =ROUND($B$6+$B$5*F40,1) -> 85.2 | I40: =G40-H40 -> -4.1 | J40: =ABS(I40) -> 4.1 | K40: =I40^2 -> 16.81 | L40: =ABS((G40-H40)/G40) -> 0.050554871
...

Sheet 🔬 ToolPak_Output
A1: ToolPak Regression Output — Annotated (Data → Data Analysis → Regression)
A2: HOW TO RUN: Data tab → Data Analysis → Regression → Y Range: Score column → X Range: StudyHours column → ✓ Labels → ✓ Residuals → OK
A4: SECTION 1 — Regression Statistics (Model Quality)
A5: Metric | B5: Value | C5: What It Means | D5: Good Value? | E5: Your Value
A6: Multiple R | B6: =CORREL('📊 RawData'!G3:G82,'📊 RawData'!D3:D82) -> 0.59100712 | C6: Correlation between predicted and actual. Same as r. | D6: +0.6 to +1.0 = good
A7: R Square | B7: =RSQ('📊 RawData'!G3:G82,'📊 RawData'!D3:D82) -> 0.34928941 | C7: % of score variance explained by the model. R² = r² | D7: >0.5 = moderate, >0.7 = strong
A8: Adjusted R Square | B8: =1-(1-B7)*(80-1)/(80-1-1) -> 0.34094697 | C8: R² penalised for number of features. More honest than R² | D8: Should be close to R². Big drop = overfitting
A9: Standard Error | B9: 6.6288 | C9: Average prediction error in score points. Lower = better | D9: <10 for score predictions
A10: Observations | B10: =COUNT('📊 RawData'!D3:D82) -> 80 | C10: Number of data rows used to train the model | D10: Should equal your dataset size (80)
A12: SECTION 2 — ANOVA Table (Is the Model Statistically Significant?)
A13: Source | B13: df | C13: SS (Sum Squares) | D13: MS (Mean Sq) | E13: F Statistic | F13: Sig F (p-value) | G13: Interpretation
A14: Regression | B14: 1 | C14: =B7*DEVSQ('📊 RawData'!G3:G82) -> 1839.7884 | D14: =C14/B14 -> 1839.7884 | E14: =D14/D15 -> 41.868958 | F14: =IF(E14>3.96,"< 0.05 ✓ SIGNIFICANT","≥ 0.05 ✗ NOT SIG") -> < 0.05 ✓ SIGNIFICANT | G14: If Sig F < 0.05: at least one feature significantly predicts the target
A15: Residual | B15: 78 | C15: =(1-B7)*DEVSQ('📊 RawData'!G3:G82) -> 3427.4436 | D15: =C15/B15 -> 43.941585 | E15: — | F15: — | G15: Residual = variance the model could NOT explain
A16: Total | B16: 79 | C16: =DEVSQ('📊 RawData'!G3:G82) -> 5267.232 | D16: — | E16: — | F16: — | G16: Regression SS + Residual SS = Total SS
A18: SECTION 3 — Coefficients Table (Most Important Section!)
A19: Variable | B19: Coefficient | C19: Std Error | D19: t Statistic | E19: p-value | F19: Lower 95% | G19: Upper 95% | H19: Significant? | I19: Interpretation
A20: Intercept | B20: =INTERCEPT('📊 RawData'!G3:G82,'📊 RawData'!D3:D82) -> 75.240706 | C20: =B9/4 -> 1.6572 | D20: =B20/C20 -> 45.402308 | E20: =IF(ABS(D20)>2,"< 0.05 ✓","≥ 0.05 ✗") -> < 0.05 ✓ | F20: =B20-1.96*C20 -> 71.992594 | G20: =B20+1.96*C20 -> 78.488818 | H20: =IF(ABS(D20)>2,"✓ YES","✗ NO") -> ✓ YES | I20: Predicted score when all inputs = 0 (baseline score)
A21: StudyHours | B21: =SLOPE('📊 RawData'!G3:G82,'📊 RawData'!D3:D82) -> 2.9341594 | C21: =STDEV('📊 RawData'!G3:G82)*SQRT(1-RSQ('📊 RawData'!G3:G82,'📊 RawData'!D3:D82))*SQRT(79/78) -> 6.6288449 | D21: =B21/C21 -> 0.4426351 | E21: =IF(ABS(D21)>2,"< 0.05 ✓","≥ 0.05 ✗") -> ≥ 0.05 ✗ | F21: =B21-1.96*C21 -> -10.058377 | G21: =B21+1.96*C21 -> 15.926695 | H21: =IF(ABS(D21)>2,"✓ YES","✗ NO") -> ✗ NO | I21: Each extra study hour predicts this many more exam points
A23: HOW TO READ THIS OUTPUT
A24: Coefficient (Col B) | B24: → | C24: The effect size. β₁=4.2 means: 1 extra study hour predicts 4.2 more exam points.
A25: p-value (Col E) | B25: → | C25: < 0.05 = feature is statistically significant. ≥ 0.05 = could be random noise — consider dropping.
A26: 95% CI (Cols F–G) | B26: → | C26: Range the true coefficient likely falls in. If it crosses zero, effect may not be real.
A27: R Square (Sheet top) | B27: → | C27: 0.67 means study hours explains 67% of score differences. The other 33% = unmeasured factors.
A28: Std Error (Sheet top) | B28: → | C28: If Std Error = 6.2: predictions typically within ±6.2 score points of the real score.
A29: Sig F (ANOVA) | B29: → | C29: Overall model significance. < 0.05 = your model is better than just predicting the mean.

Sheet 🔢 MultipleRegression
A1: Multiple Linear Regression — 3 Features + Backward Elimination
A2: Uses StudyHours + Attendance% + Is_Eng. Backward Elimination removes features with p > 0.05. Compare Adj R² before and after.
A4: Trained Coefficients (Full Model) | F4: Predictions + Residuals (Multiple Regression)
A5: Parameter | B5: Value | C5: Formula Used | D5: Plain English Meaning | F5: StudyHrs | G5: Attend% | H5: Is_Eng | I5: ActualScore | J5: Predicted | K5: Residual | L5: AbsErr | M5: SqErr | N5: Pct_Err
A6: β₀ (Intercept) | B6: 47.5674 | C6: INTERCEPT(Score, [StudyHours,Attendance]) | D6: Baseline score when all features = 0 | F6: ='📊 RawData'!D3 -> 5.3 | G6: ='📊 RawData'!E3 -> 84.6 | H6: ='📊 RawData'!I3 -> 0 | I6: ='📊 RawData'!G3 -> 100 | J6: =ROUND($B$6+$B$7*F6+$B$8*G6+$B$9*H6,1) -> 90.7 | K6: =I6-J6 -> 9.3 | L6: =ABS(K6) -> 9.3 | M6: =K6^2 -> 86.49 | N6: =ABS((I6-J6)/I6) -> 0.093
A7: β₁ (StudyHours) | B7: 2.9258 | C7: LINEST 2nd coefficient | D7: Score gain per extra study hour (holding Attendance constant) | F7: ='📊 RawData'!D4 -> 3 | G7: ='📊 RawData'!E4 -> 89.2 | H7: ='📊 RawData'!I4 -> 1 | I7: ='📊 RawData'!G4 -> 84.8 | J7: =ROUND($B$6+$B$7*F7+$B$8*G7+$B$9*H7,1) -> 90.1 | K7: =I7-J7 -> -5.3 | L7: =ABS(K7) -> 5.3 | M7: =K7^2 -> 28.09 | N7: =ABS((I7-J7)/I7) -> 0.0625
A8: β₂ (Attendance) | B8: 0.3268 | C8: LINEST 1st coefficient | D8: Score gain per 1% increase in Attendance (holding StudyHours constant) | F8: ='📊 RawData'!D5 -> 2.8 | G8: ='📊 RawData'!E5 -> 85.2 | H8: ='📊 RawData'!I5 -> 0 | I8: ='📊 RawData'!G5 -> 92.8 | J8: =ROUND($B$6+$B$7*F8+$B$8*G8+$B$9*H8,1) -> 83.6 | K8: =I8-J8 -> 9.2 | L8: =ABS(K8) -> 9.2 | M8: =K8^2 -> 84.64 | N8: =ABS((I8-J8)/I8) -> 0.099137931
A9: β₃ (Is_Eng) | B9: 4.6281 | C9: LINEST — Engineering dummy | D9: Extra score for Engineering students vs reference group | F9: ='📊 RawData'!D6 -> 2.9 | G9: ='📊 RawData'!E6 -> 88.8 | H9: ='📊 RawData'!I6 -> 0 | I9: ='📊 RawData'!G6 -> 88.9 | J9: =ROUND($B$6+$B$7*F9+$B$8*G9+$B$9*H9,1) -> 85.1 | K9: =I9-J9 -> 3.8 | L9: =ABS(K9) -> 3.8 | M9: =K9^2 -> 14.44 | N9: =ABS((I9-J9)/I9) -> 0.042744657
A10: R² (Full Model) | B10: 0.5863 | C10: RSQ(Score, [StudyHours,Attendance]) | D10: % of score variance explained by all 3 features combined | F10: ='📊 RawData'!D7 -> 2.7 | G10: ='📊 RawData'!E7 -> 100 | H10: ='📊 RawData'!I7 -> 0 | I10: ='📊 RawData'!G7 -> 85.5 | J10: =ROUND($B$6+$B$7*F10+$B$8*G10+$B$9*H10,1) -> 88.1 | K10: =I10-J10 -> -2.6 | L10: =ABS(K10) -> 2.6 | M10: =K10^2 -> 6.76 | N10: =ABS((I10-J10)/I10) -> 0.030409357
A11: Adj R² | B11: 5.3547 | C11: 1-(1-R²)×(n-1)/(n-k-1) | D11: Penalised R². Better metric when comparing models with different features | F11: ='📊 RawData'!D8 -> 3.8 | G11: ='📊 RawData'!E8 -> 83 | H11: ='📊 RawData'!I8 -> 0 | I11: ='📊 RawData'!G8 -> 83.9 | J11: =ROUND($B$6+$B$7*F11+$B$8*G11+$B$9*H11,1) -> 85.8 | K11: =I11-J11 -> -1.9 | L11: =ABS(K11) -> 1.9 | M11: =K11^2 -> 3.61 | N11: =ABS((I11-J11)/I11) -> 0.022646007
A12: Std Error | B12: =SQRT(SUMXMY2('📊 RawData'!G3:G82,F6:F85)/76) -> 87.030674 | C12: SQRT(SUMXMY2(actual,pred)/df) | D12: Average prediction error in score points | F12: ='📊 RawData'!D9 -> 3 | G12: ='📊 RawData'!E9 -> 75.4 | H12: ='📊 RawData'!I9 -> 0 | I12: ='📊 RawData'!G9 -> 74.2 | J12: =ROUND($B$6+$B$7*F12+$B$8*G12+$B$9*H12,1) -> 81 | K12: =I12-J12 -> -6.8 | L12: =ABS(K12) -> 6.8 | M12: =K12^2 -> 46.24 | N12: =ABS((I12-J12)/I12) -> 0.091644205
F13: ='📊 RawData'!D10 -> 4.2 | G13: ='📊 RawData'!E10 -> 84 | H13: ='📊 RawData'!I10 -> 0 | I13: ='📊 RawData'!G10 -> 85 | J13: =ROUND($B$6+$B$7*F13+$B$8*G13+$B$9*H13,1) -> 87.3 | K13: =I13-J13 -> -2.3 | L13: =ABS(K13) -> 2.3 | M13: =K13^2 -> 5.29 | N13: =ABS((I13-J13)/I13) -> 0.027058824
A14: FULL MODEL EQUATION: | F14: ='📊 RawData'!D11 -> 0.8 | G14: ='📊 RawData'!E11 -> 60.3 | H14: ='📊 RawData'!I11 -> 0 | I14: ='📊 RawData'!G11 -> 64 | J14: =ROUND($B$6+$B$7*F14+$B$8*G14+$B$9*H14,1) -> 69.6 | K14: =I14-J14 -> -5.6 | L14: =ABS(K14) -> 5.6 | M14: =K14^2 -> 31.36 | N14: =ABS((I14-J14)/I14) -> 0.0875
A15: =CONCATENATE("Score = ",TEXT(B6,"0.00")," + ",TEXT(B7,"0.00")," × StudyHours + ",TEXT(B8,"0.00")," × Attendance + ",TEXT(B9,"0.00")," × Is_Eng") -> Score = 47.57 + 2.93 × StudyHours + 0.33 × Attendance + 4.63 × Is_Eng | F15: ='📊 RawData'!D12 -> 7 | G15: ='📊 RawData'!E12 -> 79.8 | H15: ='📊 RawData'!I12 -> 1 | I15: ='📊 RawData'!G12 -> 99.9 | J15: =ROUND($B$6+$B$7*F15+$B$8*G15+$B$9*H15,1) -> 98.8 | K15: =I15-J15 -> 1.1 | L15: =ABS(K15) -> 1.1 | M15: =K15^2 -> 1.21 | N15: =ABS((I15-J15)/I15) -> 0.011011011
F16: ='📊 RawData'!D13 -> 6.3 | G16: ='📊 RawData'!E13 -> 82.9 | H16: ='📊 RawData'!I13 -> 0 | I16: ='📊 RawData'!G13 -> 94.4 | J16: =ROUND($B$6+$B$7*F16+$B$8*G16+$B$9*H16,1) -> 93.1 | K16: =I16-J16 -> 1.3 | L16: =ABS(K16) -> 1.3 | M16: =K16^2 -> 1.69 | N16: =ABS((I16-J16)/I16) -> 0.013771186
F17: ='📊 RawData'!D14 -> 6 | G17: ='📊 RawData'!E14 -> 96.4 | H17: ='📊 RawData'!I14 -> 0 | I17: ='📊 RawData'!G14 -> 98.5 | J17: =ROUND($B$6+$B$7*F17+$B$8*G17+$B$9*H17,1) -> 96.6 | K17: =I17-J17 -> 1.9 | L17: =ABS(K17) -> 1.9 | M17: =K17^2 -> 3.61 | N17: =ABS((I17-J17)/I17) -> 0.01928934
A18: Model Comparison — Single vs Multiple Feature | F18: ='📊 RawData'!D15 -> 2.5 | G18: ='📊 RawData'!E15 -> 88.6 | H18: ='📊 RawData'!I15 -> 1 | I18: ='📊 RawData'!G15 -> 93.3 | J18: =ROUND($B$6+$B$7*F18+$B$8*G18+$B$9*H18,1) -> 88.5 | K18: =I18-J18 -> 4.8 | L18: =ABS(K18) -> 4.8 | M18: =K18^2 -> 23.04 | N18: =ABS((I18-J18)/I18) -> 0.051446945
A19: Model | B19: Features Used | C19: R² | D19: Adj R² | F19: ='📊 RawData'!D16 -> 7.4 | G19: ='📊 RawData'!E16 -> 94.1 | H19: ='📊 RawData'!I16 -> 0 | I19: ='📊 RawData'!G16 -> 97.4 | J19: =ROUND($B$6+$B$7*F19+$B$8*G19+$B$9*H19,1) -> 100 | K19: =I19-J19 -> -2.6 | L19: =ABS(K19) -> 2.6 | M19: =K19^2 -> 6.76 | N19: =ABS((I19-J19)/I19) -> 0.026694045
A20: Model 1 — Simple | B20: StudyHours only | C20: 0.3493 | D20: 0.341 | F20: ='📊 RawData'!D17 -> 4.3 | G20: ='📊 RawData'!E17 -> 80.7 | H20: ='📊 RawData'!I17 -> 0 | I20: ='📊 RawData'!G17 -> 91 | J20: =ROUND($B$6+$B$7*F20+$B$8*G20+$B$9*H20,1) -> 86.5 | K20: =I20-J20 -> 4.5 | L20: =ABS(K20) -> 4.5 | M20: =K20^2 -> 20.25 | N20: =ABS((I20-J20)/I20) -> 0.049450549
A21: Model 2 — Two Features | B21: StudyHours + Attendance | C21: 0.5513 | D21: 0.5396 | F21: ='📊 RawData'!D18 -> 5.7 | G21: ='📊 RawData'!E18 -> 83.9 | H21: ='📊 RawData'!I18 -> 1 | I21: ='📊 RawData'!G18 -> 94.1 | J21: =ROUND($B$6+$B$7*F21+$B$8*G21+$B$9*H21,1) -> 96.3 | K21: =I21-J21 -> -2.2 | L21: =ABS(K21) -> 2.2 | M21: =K21^2 -> 4.84 | N21: =ABS((I21-J21)/I21) -> 0.023379384
A22: Model 3 — Three Features | B22: StudyHours + Attendance + Is_Eng | C22: 0.5863 | D22: 0.57 | F22: ='📊 RawData'!D19 -> 5.5 | G22: ='📊 RawData'!E19 -> 73.5 | H22: ='📊 RawData'!I19 -> 0 | I22: ='📊 RawData'!G19 -> 87.4 | J22: =ROUND($B$6+$B$7*F22+$B$8*G22+$B$9*H22,1) -> 87.7 | K22: =I22-J22 -> -0.3 | L22: =ABS(K22) -> 0.3 | M22: =K22^2 -> 0.09 | N22: =ABS((I22-J22)/I22) -> 0.0034324943
A23: KEY INSIGHT: Compare Adj R² across models. If Adj R² increases when adding a feature → keep it. If it drops → the feature adds noise, not signal. Use HIGHEST Adj R² model. | F23: ='📊 RawData'!D20 -> 4.4 | G23: ='📊 RawData'!E20 -> 92.2 | H23: ='📊 RawData'!I20 -> 1 | I23: ='📊 RawData'!G20 -> 96.3 | J23: =ROUND($B$6+$B$7*F23+$B$8*G23+$B$9*H23,1) -> 95.2 | K23: =I23-J23 -> 1.1 | L23: =ABS(K23) -> 1.1 | M23: =K23^2 -> 1.21 | N23: =ABS((I23-J23)/I23) -> 0.011422638
F24: ='📊 RawData'!D21 -> 5.8 | G24: ='📊 RawData'!E21 -> 68 | H24: ='📊 RawData'!I21 -> 0 | I24: ='📊 RawData'!G21 -> 90.4 | J24: =ROUND($B$6+$B$7*F24+$B$8*G24+$B$9*H24,1) -> 86.8 | K24: =I24-J24 -> 3.6 | L24: =ABS(K24) -> 3.6 | M24: =K24^2 -> 12.96 | N24: =ABS((I24-J24)/I24) -> 0.039823009
F25: ='📊 RawData'!D22 -> 8 | G25: ='📊 RawData'!E22 -> 60.9 | H25: ='📊 RawData'!I22 -> 1 | I25: ='📊 RawData'!G22 -> 94.5 | J25: =ROUND($B$6+$B$7*F25+$B$8*G25+$B$9*H25,1) -> 95.5 | K25: =I25-J25 -> -1 | L25: =ABS(K25) -> 1 | M25: =K25^2 -> 1 | N25: =ABS((I25-J25)/I25) -> 0.010582011
F26: ='📊 RawData'!D23 -> 4 | G26: ='📊 RawData'!E23 -> 92.9 | H26: ='📊 RawData'!I23 -> 0 | I26: ='📊 RawData'!G23 -> 83.3 | J26: =ROUND($B$6+$B$7*F26+$B$8*G26+$B$9*H26,1) -> 89.6 | K26: =I26-J26 -> -6.3 | L26: =ABS(K26) -> 6.3 | M26: =K26^2 -> 39.69 | N26: =ABS((I26-J26)/I26) -> 0.075630252
F27: ='📊 RawData'!D24 -> 4.8 | G27: ='📊 RawData'!E24 -> 70.4 | H27: ='📊 RawData'!I24 -> 0 | I27: ='📊 RawData'!G24 -> 76.6 | J27: =ROUND($B$6+$B$7*F27+$B$8*G27+$B$9*H27,1) -> 84.6 | K27: =I27-J27 -> -8 | L27: =ABS(K27) -> 8 | M27: =K27^2 -> 64 | N27: =ABS((I27-J27)/I27) -> 0.10443864
F28: ='📊 RawData'!D25 -> 4.1 | G28: ='📊 RawData'!E25 -> 95.6 | H28: ='📊 RawData'!I25 -> 1 | I28: ='📊 RawData'!G25 -> 98 | J28: =ROUND($B$6+$B$7*F28+$B$8*G28+$B$9*H28,1) -> 95.4 | K28: =I28-J28 -> 2.6 | L28: =ABS(K28) -> 2.6 | M28: =K28^2 -> 6.76 | N28: =ABS((I28-J28)/I28) -> 0.026530612
F29: ='📊 RawData'!D26 -> 4.9 | G29: ='📊 RawData'!E26 -> 91 | H29: ='📊 RawData'!I26 -> 0 | I29: ='📊 RawData'!G26 -> 85.1 | J29: =ROUND($B$6+$B$7*F29+$B$8*G29+$B$9*H29,1) -> 91.6 | K29: =I29-J29 -> -6.5 | L29: =ABS(K29) -> 6.5 | M29: =K29^2 -> 42.25 | N29: =ABS((I29-J29)/I29) -> 0.076380729
F30: ='📊 RawData'!D27 -> 0.9 | G30: ='📊 RawData'!E27 -> 72.7 | H30: ='📊 RawData'!I27 -> 0 | I30: ='📊 RawData'!G27 -> 83.7 | J30: =ROUND($B$6+$B$7*F30+$B$8*G30+$B$9*H30,1) -> 74 | K30: =I30-J30 -> 9.7 | L30: =ABS(K30) -> 9.7 | M30: =K30^2 -> 94.09 | N30: =ABS((I30-J30)/I30) -> 0.11589008
F31: ='📊 RawData'!D28 -> 3.7 | G31: ='📊 RawData'!E28 -> 65.3 | H31: ='📊 RawData'!I28 -> 0 | I31: ='📊 RawData'!G28 -> 86.6 | J31: =ROUND($B$6+$B$7*F31+$B$8*G31+$B$9*H31,1) -> 79.7 | K31: =I31-J31 -> 6.9 | L31: =ABS(K31) -> 6.9 | M31: =K31^2 -> 47.61 | N31: =ABS((I31-J31)/I31) -> 0.079676674
F32: ='📊 RawData'!D29 -> 7.7 | G32: ='📊 RawData'!E29 -> 76.7 | H32: ='📊 RawData'!I29 -> 0 | I32: ='📊 RawData'!G29 -> 100 | J32: =ROUND($B$6+$B$7*F32+$B$8*G32+$B$9*H32,1) -> 95.2 | K32: =I32-J32 -> 4.8 | L32: =ABS(K32) -> 4.8 | M32: =K32^2 -> 23.04 | N32: =ABS((I32-J32)/I32) -> 0.048
F33: ='📊 RawData'!D30 -> 3.5 | G33: ='📊 RawData'!E30 -> 91.5 | H33: ='📊 RawData'!I30 -> 0 | I33: ='📊 RawData'!G30 -> 71.5 | J33: =ROUND($B$6+$B$7*F33+$B$8*G33+$B$9*H33,1) -> 87.7 | K33: =I33-J33 -> -16.2 | L33: =ABS(K33) -> 16.2 | M33: =K33^2 -> 262.44 | N33: =ABS((I33-J33)/I33) -> 0.22657343
F34: ='📊 RawData'!D31 -> 4.4 | G34: ='📊 RawData'!E31 -> 72.2 | H34: ='📊 RawData'!I31 -> 1 | I34: ='📊 RawData'!G31 -> 82.1 | J34: =ROUND($B$6+$B$7*F34+$B$8*G34+$B$9*H34,1) -> 88.7 | K34: =I34-J34 -> -6.6 | L34: =ABS(K34) -> 6.6 | M34: =K34^2 -> 43.56 | N34: =ABS((I34-J34)/I34) -> 0.080389769
F35: ='📊 RawData'!D32 -> 5.9 | G35: ='📊 RawData'!E32 -> 72.1 | H35: ='📊 RawData'!I32 -> 0 | I35: ='📊 RawData'!G32 -> 87.9 | J35: =ROUND($B$6+$B$7*F35+$B$8*G35+$B$9*H35,1) -> 88.4 | K35: =I35-J35 -> -0.5 | L35: =ABS(K35) -> 0.5 | M35: =K35^2 -> 0.25 | N35: =ABS((I35-J35)/I35) -> 0.0056882821
... F85: ='📊 RawData'!D82 -> 5.1 | G85: ='📊 RawData'!E82 -> 75.7 | H85: ='📊 RawData'!I82 -> 0 | I85: ='📊 RawData'!G82 -> 90.7 | J85: =ROUND($B$6+$B$7*F85+$B$8*G85+$B$9*H85,1) -> 87.2 | K85: =I85-J85 -> 3.5 | L85: =ABS(K85) -> 3.5 | M85: =K85^2 -> 12.25 | N85: =ABS((I85-J85)/I85) -> 0.038588754
F86: AVERAGES → Residual avg should ≈ 0 | J86: =AVERAGE(J6:J85) -> 89.3075 | K86: =AVERAGE(K6:K85) -> 0.0025 | L86: =AVERAGE(L6:L85) -> 4.3925 | M86: =SQRT(AVERAGE(M6:M85)) -> 5.2165362 | N86: =AVERAGE(N6:N85) -> 0.050298258

Sheet 📊 Residuals
A1: Residual Analysis — Model Health Check
A2: Residuals = Actual − Predicted. A GOOD model shows: random scatter around 0. Pattern in residuals = model is wrong in a systematic way.
A4: Row | B4: ActualScore | C4: PredictedScore | D4: Residual | E4: StdResidual | F4: Residual Pattern Diagnosis
A5: 1 | B5: ='📊 RawData'!G3 -> 100 | C5: ='🔢 MultipleRegression'!J6 -> 90.7 | D5: =B5-C5 -> 9.3 | E5: =(D5-AVERAGE($D$5:$D$84))/STDEV($D$5:$D$84) -> 1.7711387 | F5: Pattern | G5: Status | H5: Meaning | I5: Fix
A6: 2 | B6: ='📊 RawData'!G4 -> 84.8 | C6: ='🔢 MultipleRegression'!J7 -> 90.1 | D6: =B6-C6 -> -5.3 | E6: =(D6-AVERAGE($D$5:$D$84))/STDEV($D$5:$D$84) -> -1.0101062 | F6: Random scatter around 0 | G6: ✓ GOOD MODEL | H6: Assumptions met. Model is appropriate. | I6: No action needed
A7: 3 | B7: ='📊 RawData'!G5 -> 92.8 | C7: ='🔢 MultipleRegression'!J8 -> 83.6 | D7: =B7-C7 -> 9.2 | E7: =(D7-AVERAGE($D$5:$D$84))/STDEV($D$5:$D$84) -> 1.752089 | F7: Fan/funnel shape | G7: ⚠ Heteroscedasticity | H7: Variance increases with fitted values | I7: Log-transform the target variable
A8: 4 | B8: ='📊 RawData'!G6 -> 88.9 | C8: ='🔢 MultipleRegression'!J9 -> 85.1 | D8: =B8-C8 -> 3.8 | E8: =(D8-AVERAGE($D$5:$D$84))/STDEV($D$5:$D$84) -> 0.72340942 | F8: Curved arc pattern | G8: ⚠ Non-linearity | H8: Missed non-linear relationship | I8: Add feature² term or try tree model
A9: 5 | B9: ='📊 RawData'!G7 -> 85.5 | C9: ='🔢 MultipleRegression'!J10 -> 88.1 | D9: =B9-C9 -> -2.6 | E9: =(D9-AVERAGE($D$5:$D$84))/STDEV($D$5:$D$84) -> -0.49576643 | F9: Systematic blocks | G9: ⚠ Missing feature | H9: Groups not captured by model | I9: Add the missing categorical variable
A10: 6 | B10: ='📊 RawData'!G8 -> 83.9 | C10: ='🔢 MultipleRegression'!J11 -> 85.8 | D10: =B10-C10 -> -1.9 | E10: =(D10-AVERAGE($D$5:$D$84))/STDEV($D$5:$D$84) -> -0.36241907 | F10: |Std Residual| > 3 | G10: ⚠ Extreme outlier | H10: Very influential data point | I10: Investigate — data error or real extreme?
A11: 7 | B11: ='📊 RawData'!G9 -> 74.2 | C11: ='🔢 MultipleRegression'!J12 -> 81 | D11: =B11-C11 -> -6.8 | E11: =(D11-AVERAGE($D$5:$D$84))/STDEV($D$5:$D$84) -> -1.2958506 | F11: =ABS(D11) -> 6.8 | G11: =D11^2 -> 46.24 | H11: =IF(ABS(E11)>2,"⚠ INFLUENTIAL","✓ Normal") -> ✓ Normal
A12: 8 | B12: ='📊 RawData'!G10 -> 85 | C12: ='🔢 MultipleRegression'!J13 -> 87.3 | D12: =B12-C12 -> -2.3 | E12: =(D12-AVERAGE($D$5:$D$84))/STDEV($D$5:$D$84) -> -0.43861756 | F12: =ABS(D12) -> 2.3 | G12: =D12^2 -> 5.29 | H12: =IF(ABS(E12)>2,"⚠ INFLUENTIAL","✓ Normal") -> ✓ Normal
A13: 9 | B13: ='📊 RawData'!G11 -> 64 | C13: ='🔢 MultipleRegression'!J14 -> 69.6 | D13: =B13-C13 -> -5.6 | E13: =(D13-AVERAGE($D$5:$D$84))/STDEV($D$5:$D$84) -> -1.0672551 | F13: =ABS(D13) -> 5.6 | G13: =D13^2 -> 31.36 | H13: =IF(ABS(E13)>2,"⚠ INFLUENTIAL","✓ Normal") -> ✓ Normal
A14: 10 | B14: ='📊 RawData'!G12 -> 99.9 | C14: ='🔢 MultipleRegression'!J15 -> 98.8 | D14: =B14-C14 -> 1.1 | E14: =(D14-AVERAGE($D$5:$D$84))/STDEV($D$5:$D$84) -> 0.20906961 | F14: =ABS(D14) -> 1.1 | G14: =D14^2 -> 1.21 | H14: =IF(ABS(E14)>2,"⚠ INFLUENTIAL","✓ Normal") -> ✓ Normal
A15: 11 | B15: ='📊 RawData'!G13 -> 94.4 | C15: ='🔢 MultipleRegression'!J16 -> 93.1 | D15: =B15-C15 -> 1.3 | E15: =(D15-AVERAGE($D$5:$D$84))/STDEV($D$5:$D$84) -> 0.24716885 | F15: =ABS(D15) -> 1.3 | G15: =D15^2 -> 1.69 | H15: =IF(ABS(E15)>2,"⚠ INFLUENTIAL","✓ Normal") -> ✓ Normal
A16: 12 | B16: ='📊 RawData'!G14 -> 98.5 | C16: ='🔢 MultipleRegression'!J17 -> 96.6 | D16: =B16-C16 -> 1.9 | E16: =(D16-AVERAGE($D$5:$D$84))/STDEV($D$5:$D$84) -> 0.36146659 | F16: =ABS(D16) -> 1.9 | G16: =D16^2 -> 3.61 | H16: =IF(ABS(E16)>2,"⚠ INFLUENTIAL","✓ Normal") -> ✓ Normal
A17: 13 | B17: ='📊 RawData'!G15 -> 93.3 | C17: ='🔢 MultipleRegression'!J18 -> 88.5 | D17: =B17-C17 -> 4.8 | E17: =(D17-AVERAGE($D$5:$D$84))/STDEV($D$5:$D$84) -> 0.91390564 | F17: =ABS(D17) -> 4.8 | G17: =D17^2 -> 23.04 | H17: =IF(ABS(E17)>2,"⚠ INFLUENTIAL","✓ Normal") -> ✓ Normal
A18: 14 | B18: ='📊 RawData'!G16 -> 97.4 | C18: ='🔢 MultipleRegression'!J19 -> 100 | D18: =B18-C18 -> -2.6 | E18: =(D18-AVERAGE($D$5:$D$84))/STDEV($D$5:$D$84) -> -0.49576643 | F18: =ABS(D18) -> 2.6 | G18: =D18^2 -> 6.76 | H18: =IF(ABS(E18)>2,"⚠ INFLUENTIAL","✓ Normal") -> ✓ Normal
A19: 15 | B19: ='📊 RawData'!G17 -> 91 | C19: ='🔢 MultipleRegression'!J20 -> 86.5 | D19: =B19-C19 -> 4.5 | E19: =(D19-AVERAGE($D$5:$D$84))/STDEV($D$5:$D$84) -> 0.85675678 | F19: =ABS(D19) -> 4.5 | G19: =D19^2 -> 20.25 | H19: =IF(ABS(E19)>2,"⚠ INFLUENTIAL","✓ Normal") -> ✓ Normal
A20: 16 | B20: ='📊 RawData'!G18 -> 94.1 | C20: ='🔢 MultipleRegression'!J21 -> 96.3 | D20: =B20-C20 -> -2.2 | E20: =(D20-AVERAGE($D$5:$D$84))/STDEV($D$5:$D$84) -> -0.41956794 | F20: =ABS(D20) -> 2.2 | G20: =D20^2 -> 4.84 | H20: =IF(ABS(E20)>2,"⚠ INFLUENTIAL","✓ Normal") -> ✓ Normal
A21: 17 | B21: ='📊 RawData'!G19 -> 87.4 | C21: ='🔢 MultipleRegression'!J22 -> 87.7 | D21: =B21-C21 -> -0.3 | E21: =(D21-AVERAGE($D$5:$D$84))/STDEV($D$5:$D$84) -> -0.057625108 | F21: =ABS(D21) -> 0.3 | G21: =D21^2 -> 0.09 | H21: =IF(ABS(E21)>2,"⚠ INFLUENTIAL","✓ Normal") -> ✓ Normal
A22: 18 | B22: ='📊 RawData'!G20 -> 96.3 | C22: ='🔢 MultipleRegression'!J23 -> 95.2 | D22: =B22-C22 -> 1.1 | E22: =(D22-AVERAGE($D$5:$D$84))/STDEV($D$5:$D$84) -> 0.20906961 | F22: =ABS(D22) -> 1.1 | G22: =D22^2 -> 1.21 | H22: =IF(ABS(E22)>2,"⚠ INFLUENTIAL","✓ Normal") -> ✓ Normal
... A84: 80 | B84: ='📊 RawData'!G82 -> 90.7 | C84: ='🔢 MultipleRegression'!J85 -> 87.2 | D84: =B84-C84 -> 3.5 | E84: =(D84-AVERAGE($D$5:$D$84))/STDEV($D$5:$D$84) -> 0.66626055 | F84: =ABS(D84) -> 3.5 | G84: =D84^2 -> 12.25 | H84: =IF(ABS(E84)>2,"⚠ INFLUENTIAL","✓ Normal") -> ✓ Normal
A86: Residual Summary Statistics
A87: Metric | B87: Value | C87: Format | D87: Interpretation
A88: Mean Residual | B88: =AVERAGE(D5:D84) -> 0.0025 | C88: 0.0000 | D88: Should be ≈ 0.00 (mathematical property)
A89: Std Dev Residuals | B89: =STDEV(D5:D84) -> 5.2494478 | C89: 0.00 | D89: ≈ Std Error of model
A90: Max Residual | B90: =MAX(D5:D84) -> 9.7 | C90: 0.00 | D90: Largest over-prediction error
A91: Min Residual | B91: =MIN(D5:D84) -> -16.2 | C91: 0.00 | D91: Largest under-prediction error
A92: MAE | B92: =AVERAGE(F5:F84) -> 4.3148649 | C92: 0.00 | D92: Mean Absolute Error — typical error magnitude
A93: RMSE | B93: =SQRT(AVERAGE(G5:G84)) -> 5.1372382 | C93: 0.00 | D93: Root Mean Squared Error — punishes big errors
A94: Influential Pts | B94: =COUNTIF(H5:H84,"⚠ INFLUENTIAL") -> 1 | C94: 0 | D94: Rows where |Std Residual| > 2
A95: Influential % | B95: =G93/80 -> 0 | C95: 0.0% | D95: Should be < 5% of data

Sheet 🚀 ScoringEngine
A1: 🎯 Student Score Predictor — Live Regression Scoring Engine
A2: Change the YELLOW input cells below → Predicted Score updates automatically. Uses your trained Multiple Regression model.
A4: 📥 INPUT — Student Features (Yellow cells are editable)
A5: Study Hours / Day | B5: (0.5 to 10 hours) | C5: 5 | D5: ← ENTER HERE | E5: Number of hours studied per day | I5: Features Used | J5: StudyHours + Attend% + Is_Eng
A6: Attendance % | B6: (40 to 100%) | C6: 80 | D6: ← ENTER HERE | E6: Percentage of classes attended | I6: R² (Full Model) | J6: ='🔢 MultipleRegression'!B7 -> 2.9258
A7: Department | B7: (Eng / Mkt / Sci / Fin) | C7: Engineering | D7: ← ENTER HERE | E7: Student's academic department | I7: Adj R² | J7: ='🔢 MultipleRegression'!B10 -> 0.5863
I8: Std Error | J8: ='🔢 MultipleRegression'!B11 -> 5.3547
A9: ⚙ AUTO-CALCULATED — One-Hot Encoding (do not edit) | I9: MAE (Training) | J9: =AVERAGE('📊 Residuals'!F5:F84) -> 4.3148649
A10: Is_Eng (auto) | C10: =IF(C7="Engineering",1,0) -> 1 | D10: ← =1 if Engineering, 0 otherwise | I10: RMSE (Training) | J10: =SQRT(AVERAGE('📊 Residuals'!G5:G84)) -> 5.1372382
A11: Is_Mkt (auto) | C11: =IF(C7="Marketing",1,0) -> 0 | D11: ← =1 if Marketing, 0 otherwise | I11: Trained on | J11: 80 students
I12: Date Trained | J12: =TODAY() -> 46163
A13: 📤 OUTPUT — Predictions
A14: Predicted Score | C14: =ROUND('🔢 MultipleRegression'!B6+'🔢 MultipleRegression'!B7*C5+'🔢 MultipleRegression'!B8*C6+'🔢 MultipleRegression'!B9*C10,1) -> 93 | D14: ← AUTO | E14: Score out of 100
A15: 95% Lower Bound | C15: =ROUND(C14-1.96*5.3547,1) -> 82.5 | D15: ← AUTO | E15: Lower confidence bound
A16: 95% Upper Bound | C16: =ROUND(C14+1.96*'🔢 MultipleRegression'!B10,1) -> 94.1 | D16: ← AUTO | E16: Upper confidence bound
A17: Grade | C17: =IF(C14>=90,"A ★",IF(C14>=80,"B",IF(C14>=70,"C",IF(C14>=60,"D","F")))) -> A ★ | D17: ← AUTO | E17: Letter grade from predicted score
A18: Pass / Fail | C18: =IF(C14>=60,"✅ PASS","❌ FAIL") -> ✅ PASS | D18: ← AUTO | E18: Pass threshold = 60
A19: Risk Level | C19: =IF(C14>=85,"🟢 Low Risk",IF(C14>=70,"🟡 Moderate",IF(C14>=55,"🟠 High Risk","🔴 Critical"))) -> 🟢 Low Risk | D19: ← AUTO | E19: Risk of failing
A20: Recommendation | C20: =IF(C14>=80,"No intervention needed",IF(C14>=65,"Monitor progress",IF(C14>=50,"Schedule tutoring","Urgent support required"))) -> No intervention needed | D20: ← AUTO | E20: Suggested action
A22: Test Scenarios — See Model in Action
A23: Scenario | B23: StudyHrs | C23: Attend% | D23: Dept | E23: Predicted | F23: Grade | G23: Risk | H23: Action
A24: High Performer | B24: 8 | C24: 92 | D24: Engineering | E24: =ROUND('🔢 MultipleRegression'!$B$6+'🔢 MultipleRegression'!$B$7*B24+'🔢 MultipleRegression'!$B$8*C24+IF(D24="Engineering",'🔢 MultipleRegression'!$B$9,0),1) -> 105.7 | F24: =IF(E24>=90,"A ★",IF(E24>=80,"B",IF(E24>=70,"C",IF(E24>=60,"D","F")))) -> A ★ | G24: =IF(E24>=85,"🟢 Low",IF(E24>=70,"🟡 Moderate",IF(E24>=55,"🟠 High","🔴 Critical"))) -> 🟢 Low | H24: =IF(E24>=80,"No action",IF(E24>=65,"Monitor",IF(E24>=50,"Tutoring","Urgent support"))) -> No action
A25: Average Student | B25: 5 | C25: 78 | D25: Marketing | E25: =ROUND('🔢 MultipleRegression'!$B$6+'🔢 MultipleRegression'!$B$7*B25+'🔢 MultipleRegression'!$B$8*C25+IF(D25="Engineering",'🔢 MultipleRegression'!$B$9,0),1) -> 87.7 | F25: =IF(E25>=90,"A ★",IF(E25>=80,"B",IF(E25>=70,"C",IF(E25>=60,"D","F")))) -> B | G25: =IF(E25>=85,"🟢 Low",IF(E25>=70,"🟡 Moderate",IF(E25>=55,"🟠 High","🔴 Critical"))) -> 🟢 Low | H25: =IF(E25>=80,"No action",IF(E25>=65,"Monitor",IF(E25>=50,"Tutoring","Urgent support"))) -> No action
A26: At-Risk Student | B26: 2 | C26: 55 | D26: Finance | E26: =ROUND('🔢 MultipleRegression'!$B$6+'🔢 MultipleRegression'!$B$7*B26+'🔢 MultipleRegression'!$B$8*C26+IF(D26="Engineering",'🔢 MultipleRegression'!$B$9,0),1) -> 71.4 | F26: =IF(E26>=90,"A ★",IF(E26>=80,"B",IF(E26>=70,"C",IF(E26>=60,"D","F")))) -> C | G26: =IF(E26>=85,"🟢 Low",IF(E26>=70,"🟡 Moderate",IF(E26>=55,"🟠 High","🔴 Critical"))) -> 🟡 Moderate | H26: =IF(E26>=80,"No action",IF(E26>=65,"Monitor",IF(E26>=50,"Tutoring","Urgent support"))) -> Monitor
A27: Good but Low Att | B27: 7 | C27: 58 | D27: Science | E27: =ROUND('🔢 MultipleRegression'!$B$6+'🔢 MultipleRegression'!$B$7*B27+'🔢 MultipleRegression'!$B$8*C27+IF(D27="Engineering",'🔢 MultipleRegression'!$B$9,0),1) -> 87 | F27: =IF(E27>=90,"A ★",IF(E27>=80,"B",IF(E27>=70,"C",IF(E27>=60,"D","F")))) -> B | G27: =IF(E27>=85,"🟢 Low",IF(E27>=70,"🟡 Moderate",IF(E27>=55,"🟠 High","🔴 Critical"))) -> 🟢 Low | H27: =IF(E27>=80,"No action",IF(E27>=65,"Monitor",IF(E27>=50,"Tutoring","Urgent support"))) -> No action

Sheet 📋 How_To_Guide
A1: Day 6 — Step-by-Step Guide for Every Task
A3: TASK 1 — Manual Simple Regression
A4: Step 1 - Sheet | B4: Go to 📉 SimpleRegression sheet. Look at the Parameter Panel (rows 5 to 10).
A5: β₁ (Slope) | B5: Use SLOPE(Score_range, StudyHours_range) — already in cell B5. This is how many score points each extra study hour is worth.
A6: β₀ (Intercept) | B6: Use INTERCEPT(Score_range, StudyHours_range) — in cell B6. This is the predicted score for zero study hours.
A7: Predicted Score | B7: Column H = β₀ + β₁ × StudyHours. Verify: AVERAGE(Residuals) in row 85 ≈ 0.
A8: R² meaning | B8: B7 shows R². If R²=0.67: study hours explains 67% of score differences. Other 33% = unmeasured factors.
A9: Forecast table | B9: Rows 22–31 show predictions for 1–10 hours with 95% confidence intervals. Change column A to see new predictions.
A10: Chart | B10: Scatter chart shows data points (blue dots) and regression line (green). Line should pass through the middle of the cloud.
A12: TASK 2 — Read ToolPak Output
A13: How to run ToolPak | B13: Data tab → Data Analysis → Regression. Y Range = Score. X Range = StudyHours. ✓ Labels. ✓ Residuals. Click OK.
A14: Section 1 — R² | B14: Go to 🔬 ToolPak_Output. R² in row 7. Values ≥ 0.5 are meaningful. Adjusted R² is more honest (penalises extra features).
A15: Section 2 — ANOVA | B15: Row 14: Significance F < 0.05 means the model is statistically better than predicting the mean. This is the 'overall' significance.
A16: Section 3 — Coefficients | B16: Rows 20–21. The Coefficient (col B) = β value. The p-value (col E) tells you if that feature is statistically real.
A17: p-value rule | B17: p < 0.05 → feature is significant → keep it. p ≥ 0.05 → could be noise → consider dropping.
A18: 95% CI | B18: Columns F–G. If both bounds are same sign (both positive or both negative) → effect is real. If CI crosses zero → effect uncertain.
A19: Std Error | B19: B9 = average prediction error in score points. E.g. 6.2 means predictions typically within ±6 points of real score.
A21: TASK 3 — Multiple Regression
A22: Go to sheet | B22: Open 🔢 MultipleRegression. The model uses StudyHours + Attendance% + Is_Eng.
A23: Model equation | B23: Row 15 shows: Score = β₀ + β₁×StudyHours + β₂×Attendance + β₃×Is_Eng. Each β is auto-calculated with LINEST.
A24: Backward elimination | B24: Start with all 3 features. If any has p > 0.05 in ToolPak output, remove it and re-run. Compare Adj R².
A25: Model comparison | B25: Rows 20–22 compare 1-feature, 2-feature, 3-feature models. The model with HIGHEST Adj R² is best.
A26: Why Adj R²? | B26: Adding any feature (even useless ones) increases R². Adj R² penalises extra features — only increases if feature genuinely helps.
A27: Predictions | B27: Column J shows predicted scores for all 80 students. Column K = residuals. Row 86 = summary metrics.
A28: Check residuals | B28: AVERAGE(Residuals) in K86 ≈ 0. RMSE in M86 = typical prediction error. Lower is better.
A30: TASK 4 — Residual Analysis
A31: Go to sheet | B31: Open 📊 Residuals. Column D = Residuals (Actual − Predicted). Column E = Standardised Residuals.
A32: What to look for | B32: Good model: residuals are random scatter around 0. No pattern, no curve, no funnel shape.
A33: Standardised residuals | B33: Column E: values > 2 or < -2 are flagged ⚠ INFLUENTIAL in column H.
A34: Pattern diagnosis | B34: Rows 6–10 show: what each residual pattern means and how to fix it.
A35: Fan shape | B35: If residuals get wider as predicted score increases → heteroscedasticity. Fix: log-transform target.
A36: Curved pattern | B36: If residuals form a curve → non-linear relationship missed. Fix: add StudyHours² as a feature.
A37: Action | B37: If < 5% of rows are INFLUENTIAL (col H row 88 shows %) → model is fine. If > 5% → investigate those rows.
A39: TASK 5 — Scoring Engine
A40: Go to sheet | B40: Open 🚀 ScoringEngine. Type new values into the YELLOW cells (C5, C6, C7).
A41: Study Hours | B41: Cell C5 — type any number 0.5 to 10.
A42: Attendance % | B42: Cell C6 — type any number 40 to 100.
A43: Department | B43: Cell C7 — type exactly: Engineering, Marketing, Science, or Finance (case sensitive).
A44: Outputs update | B44: Rows 14–20 update automatically: Predicted Score, Grade (A–F), Pass/Fail, Risk Level, Recommendation.
A45: Confidence interval | B45: Rows 15–16 show 95% CI. Prediction ± 1.96 × Std Error. E.g. 74 ± 12 means [62, 86].
...

Sheet 📋 ModelCard
A1: 📋 Model Card — Day 6 Linear Regression
A3: PROJECT DETAILS
A4: Project Name | B4: Student Exam Score Predictor
A5: Model Type | B5: Multiple Linear Regression
A6: Target Variable | B6: Exam Score (0–100, continuous)
A7: Problem Type | B7: Regression — predict a numeric value
A8: Training Date | B8: =TODAY() -> 46163
A9: Trained By | B9: [Your Name]
A11: DATA
A12: Dataset Size | B12: 80 rows (students)
A13: Features Used | B13: StudyHours, Attendance%, Is_Eng (one-hot)
A14: Features Dropped | B14: Income — R²=0.002, no predictive value
A15: Missing Values | B15: 0 (cleaned in Day 4)
A16: Encoding | B16: Department → one-hot (Is_Eng, Is_Mkt)
A17: Scaling | B17: Not applied (linear regression doesn't require it)
A19: PERFORMANCE
A20: R² (3-feature model) | B20: ='🔢 MultipleRegression'!B9 -> 4.6281
A21: Adjusted R² | B21: ='🔢 MultipleRegression'!B10 -> 0.5863
A22: Standard Error | B22: ='🔢 MultipleRegression'!B11 -> 5.3547
A23: MAE (Training) | B23: =AVERAGE('📊 Residuals'!F5:F84) -> 4.3148649
A24: RMSE (Training) | B24: =SQRT(AVERAGE('📊 Residuals'!G5:G84)) -> 5.1372382
A25: Baseline MAE (predict mean) | B25: =AVERAGE(ABS('📊 RawData'!G3:G82-AVERAGE('📊 RawData'!G3:G82))) -> 8.69
A27: MODEL EQUATION
A28: Full Equation | B28: Score = β₀ + β₁×StudyHours + β₂×Attendance + β₃×Is_Eng
A29: β₀ (Intercept) | B29: ='🔢 MultipleRegression'!B6 -> 47.5674
A30: β₁ (StudyHours effect) | B30: ='🔢 MultipleRegression'!B7 -> 2.9258
A31: β₂ (Attendance effect) | B31: ='🔢 MultipleRegression'!B8 -> 0.3268
A32: β₃ (Engineering bonus) | B32: ='🔢 MultipleRegression'!B8 -> 0.3268
A33: Interpret β₁ | B33: For every 1 extra study hour (holding others constant), predicted score increases by β₁ points
A35: LIMITATIONS
A36: Sample Size | B36: Only 80 rows — small for production use. Minimum recommended: 200+
A37: No Test Split | B37: Metrics are training metrics — overfitting cannot be detected (addressed in Day 9)
A38: Linear Only | B38: Assumes linear relationship. Non-linear patterns are missed.
A39: Missing Features | B39: Prior grades, study quality, mental health not captured
A40: Department Encoding | B40: Only Eng included — other depts treated as one group
A41: Do NOT use for | B41: Predicting scores for students outside the training cohort without validation
A43: NEXT STEPS
A44: Day 9 Action | B44: Create train/test split, calculate Test RMSE to check generalisation
A45: Add Features | B45: Include SleepHours, PrevGrade, StudyMethod for better R²
A46: Try Classification | B46: If target is Pass/Fail → switch to logistic regression (Day 7)
...
